[2017-12-06 12:55:01 +0000] [18894] [INFO] Starting gunicorn 19.6.0
[2017-12-06 12:55:01 +0000] [18894] [ERROR] Connection in use: ('0.0.0.0', 5000)
[2017-12-06 12:55:01 +0000] [18894] [ERROR] Retrying in 1 second.
[2017-12-06 12:55:02 +0000] [18894] [ERROR] Connection in use: ('0.0.0.0', 5000)
[2017-12-06 12:55:02 +0000] [18894] [ERROR] Retrying in 1 second.
[2017-12-06 12:55:03 +0000] [18894] [ERROR] Connection in use: ('0.0.0.0', 5000)
[2017-12-06 12:55:03 +0000] [18894] [ERROR] Retrying in 1 second.
[2017-12-06 12:55:04 +0000] [18894] [ERROR] Connection in use: ('0.0.0.0', 5000)
[2017-12-06 12:55:04 +0000] [18894] [ERROR] Retrying in 1 second.
[2017-12-06 12:55:05 +0000] [18894] [ERROR] Connection in use: ('0.0.0.0', 5000)
[2017-12-06 12:55:05 +0000] [18894] [ERROR] Retrying in 1 second.
[2017-12-06 12:55:06 +0000] [18894] [ERROR] Can't connect to ('0.0.0.0', 5000)
[2017-12-06 12:55:37 +0000] [18899] [INFO] Starting gunicorn 19.6.0
[2017-12-06 12:55:37 +0000] [18899] [INFO] Listening at: http://0.0.0.0:5000 (18899)
[2017-12-06 12:55:37 +0000] [18899] [INFO] Using worker: sync
[2017-12-06 12:55:37 +0000] [18903] [INFO] Booting worker with pid: 18903
[2017-12-06 12:55:37 +0000] [18903] [ERROR] Exception in worker process
Traceback (most recent call last):
  File "/usr/lib/python2.7/dist-packages/gunicorn/arbiter.py", line 557, in spawn_worker
    worker.init_process()
  File "/usr/lib/python2.7/dist-packages/gunicorn/workers/base.py", line 126, in init_process
    self.load_wsgi()
  File "/usr/lib/python2.7/dist-packages/gunicorn/workers/base.py", line 136, in load_wsgi
    self.wsgi = self.app.wsgi()
  File "/usr/lib/python2.7/dist-packages/gunicorn/app/base.py", line 67, in wsgi
    self.callable = self.load()
  File "/usr/lib/python2.7/dist-packages/gunicorn/app/wsgiapp.py", line 65, in load
    return self.load_wsgiapp()
  File "/usr/lib/python2.7/dist-packages/gunicorn/app/wsgiapp.py", line 52, in load_wsgiapp
    return util.import_app(self.app_uri)
  File "/usr/lib/python2.7/dist-packages/gunicorn/util.py", line 384, in import_app
    __import__(module)
  File "/var/www/sgo/app/__init__.py", line 8
SyntaxError: Non-ASCII character '\xd0' in file /var/www/sgo/app/__init__.py on line 8, but no encoding declared; see http://python.org/dev/peps/pep-0263/ for details
[2017-12-06 12:55:37 +0000] [18903] [INFO] Worker exiting (pid: 18903)
[2017-12-06 12:55:37 +0000] [18899] [INFO] Shutting down: Master
[2017-12-06 12:55:37 +0000] [18899] [INFO] Reason: Worker failed to boot.
[2017-12-06 12:55:40 +0000] [18905] [INFO] Starting gunicorn 19.6.0
[2017-12-06 12:55:40 +0000] [18905] [INFO] Listening at: http://0.0.0.0:5000 (18905)
[2017-12-06 12:55:40 +0000] [18905] [INFO] Using worker: sync
[2017-12-06 12:55:40 +0000] [18909] [INFO] Booting worker with pid: 18909
[2017-12-06 12:55:40 +0000] [18909] [ERROR] Exception in worker process
Traceback (most recent call last):
  File "/usr/lib/python2.7/dist-packages/gunicorn/arbiter.py", line 557, in spawn_worker
    worker.init_process()
  File "/usr/lib/python2.7/dist-packages/gunicorn/workers/base.py", line 126, in init_process
    self.load_wsgi()
  File "/usr/lib/python2.7/dist-packages/gunicorn/workers/base.py", line 136, in load_wsgi
    self.wsgi = self.app.wsgi()
  File "/usr/lib/python2.7/dist-packages/gunicorn/app/base.py", line 67, in wsgi
    self.callable = self.load()
  File "/usr/lib/python2.7/dist-packages/gunicorn/app/wsgiapp.py", line 65, in load
    return self.load_wsgiapp()
  File "/usr/lib/python2.7/dist-packages/gunicorn/app/wsgiapp.py", line 52, in load_wsgiapp
    return util.import_app(self.app_uri)
  File "/usr/lib/python2.7/dist-packages/gunicorn/util.py", line 384, in import_app
    __import__(module)
  File "/var/www/sgo/app/__init__.py", line 8
SyntaxError: Non-ASCII character '\xd0' in file /var/www/sgo/app/__init__.py on line 8, but no encoding declared; see http://python.org/dev/peps/pep-0263/ for details
[2017-12-06 12:55:40 +0000] [18909] [INFO] Worker exiting (pid: 18909)
[2017-12-06 12:55:40 +0000] [18905] [INFO] Shutting down: Master
[2017-12-06 12:55:40 +0000] [18905] [INFO] Reason: Worker failed to boot.
